<mujoco model="franka">

   <compiler angle="radian" inertiafromgeom="true" meshdir="meshes/" />
   <option timestep="0.002"/>
   <size nuser_actuator="5"/>

   <asset>
        <mesh name="link0_col" file="collision/link0.stl"/>
        <mesh name="link1_col" file="collision/link1.stl"/>
        <mesh name="link2_col" file="collision/link2.stl"/>
        <mesh name="link3_col" file="collision/link3.stl"/>
        <mesh name="link4_col" file="collision/link4.stl"/>
        <mesh name="link5_col" file="collision/link5.stl"/>
        <mesh name="link6_col" file="collision/link6.stl"/>
        <mesh name="link7_col" file="collision/link7.stl"/>
        <mesh name="sensor_col" file="collision/sensor.stl"/>
        <mesh name="grind_col" file="collision/grind.stl"/>
        <mesh name="endscop_col" file="collision/endscop.stl"/>
        <mesh name="bed_col" file="collision/bed.stl"/>
        <mesh name="platform_col" file="collision/platform.stl"/>
        <mesh name="carm_col" file="collision/carm.stl"/>
        <mesh name="bone_col" file="collision/bone.stl"/>
        <mesh name="tool3_col" file="collision/tool3.stl"/>
        <mesh name="bone_part_col" file="collision/bone_part.stl"/>

        <mesh name="link0_viz" file="visual/link0.stl"/>
        <mesh name="link1_viz" file="visual/link1.stl"/>
        <mesh name="link2_viz" file="visual/link2.stl"/>
        <mesh name="link3_viz" file="visual/link3.stl"/>
        <mesh name="link4_viz" file="visual/link4.stl"/>
        <mesh name="link5_viz" file="visual/link5.stl"/>
        <mesh name="link6_viz" file="visual/link6.stl"/>
        <mesh name="link7_viz" file="visual/link7.stl"/>
        <mesh name="sensor_viz" file="visual/sensor.stl"/>
        <mesh name="grind_viz" file="visual/grind.stl"/>
        <mesh name="endscop_viz" file="visual/endscop.stl"/>
        <mesh name="bed_viz" file="visual/bed.stl"/>
        <mesh name="platform_viz" file="visual/platform.stl"/>
        <mesh name="carm_viz" file="visual/carm.stl"/>
        <mesh name="bone_viz" file="visual/bone.stl"/>
        <mesh name="tool3_viz" file="visual/tool3.stl"/>
        <mesh name="bone_part_viz" file="visual/bone_part.stl"/>

        <texture name="floor_tex"   type="2d"       builtin="checker"  rgb1=".2 .3 .4" rgb2=".1 .2 .3" width="100" height="100" />
        <texture name="sky_tex"     type="skybox"   builtin="gradient" width="100"     height="100"    rgb1="1 1 1" rgb2="0.3 0.3 0.8" />

        <material name='floor_mat'      texture="floor_tex"  shininess="0.8" texrepeat="10 10" specular="0.7"  reflectance="0.5" />
    </asset>

    <default>
        <default class="panda">
            <joint pos="0 0 0" axis="0 0 1" limited="true"/>
            <position forcelimited="true" ctrllimited="true" user="1002 40 2001 -0.005 0.005"/>
            <default class="panda_viz">
                <geom contype="0" conaffinity="0" group="0" type="mesh" rgba=".95 .99 .92 1" mass="0" margin="0.001"/>
            </default>

            <default class="panda_col">
                <geom contype="1" conaffinity="1" group="3" type="mesh" rgba=".5 .6 .7 1" margin="0.001"/>
            </default>

            <default class="panda_arm">
                <joint damping="100"/>
            </default>
             <default class="panda_forearm">
                <joint damping="10"/>
            </default>
             <default class="panda_finger">
                <joint damping="100" armature='5'/>
                <geom friction="1 0.5 0.0001" solref="0.01 1" solimp="0.8 0.9 0.001" margin="0.001" user="0" rgba="0.5 0.6 0.7 .4" contype="1" conaffinity="0" condim="6" group="3" />
                <position user="1002 40 2001 -0.0001 0.0001"/>
            </default>
        </default>

        <default class="panda_overlay">
            <joint limited="false" damping="1000" armature="1" frictionloss="10"/>
            <geom contype="0" conaffinity="0" group="2" type="mesh" rgba=".42 0.42 0.42 .5"/>
        </default>
    </default>
    <visual>
        <map fogstart="3" fogend="5" znear="0.05"/>
        <quality shadowsize="6000"/>
        <scale framelength="0.1"
               framewidth="0.005"
               contactwidth="0.1"
               contactheight="0.005"
               forcewidth="0.01"
               />
    </visual>
    <!--Contacts-->
<!--    <contact>
        <exclude body1="panda0_link7" body2="bone"/>
        <exclude body1="panda1_link7" body2="bone"/>
    </contact>-->

    <worldbody>
        <light directional="true" cutoff="4" exponent="20" diffuse="1 1 1" specular="0 0 0" pos="1 1 3" dir="-.5 -0.75 -1.5"/>
        <light directional="true" cutoff="1" exponent="10" diffuse="0.5 0.5 0.5" specular="0 0 0" pos="0.73 0.02 1.05" dir="-.5 -0.75 -1.5"/>

        <geom name='floor' material="floor_mat" pos='0 0 0' size='10 10 0.1'  type='plane' />
<!--
        <body name="tool1" pos="0.6 0.2 1">
          <geom  contype="1" conaffinity="1" group="2" type="mesh" mesh="tool_col" mass="2"/>
          <geom  friction="1 1 0.0001" solref="0.01 1" solimp="0.8 0.9 0.001" margin="0.001" contype="1" conaffinity="1" size=".01 .01 .01"  type="box" rgba=".94 .1 .94 1" mass="0.1"/>
        </body>-->
<!--        <body name="box_link" pos="0.87 0 0.2">
          <geom size=".2 .3 .001"  type="box" rgba=".5 .55 .5 1"/>
        </body>
        <body name="grasp_link_1" pos="0.87 0 0.5">
          <freejoint/>
          <geom  size=".01 .01 .01"  type="box" rgba="0 .96 1 1" mass="0.1"/>
        </body>-->

        <site name='rcm_point' pos='0.594165 -4.35076e-12 0.46647' size='0.005' />

        <geom pos="-2 1 0" class="panda_viz" mesh="carm_viz"/>
        <geom pos="-2 1 0" class="panda_col" mesh="carm_col" mass="100"/>

<!--        <geom pos="0.9 -0.5 0" euler='0 0 -1.57079632679' class="panda_viz" mesh="bed_viz"/>
        <geom pos="0.9 -0.5 0" euler='0 0 -1.57079632679' class="panda_col" mesh="bed_col" mass="10"/>-->

        <body name="box_link_1" pos="0.7 0 0">
          <geom size=".2 .2 .05"  type="box" rgba=".5 .55 .5 1"/>
        </body>
        <body name="box_link_2" pos="0.7 0 0.05">
          <geom size=".05 .05 0.9"  type="box" rgba=".5 .55 .5 1"/>
        </body>
        <body name="box_link_3" pos="0.7 0 0.95">
          <geom size=".1 .1 .02"  type="box" rgba=".5 .55 .5 1"/>
        </body>
        <body name="box_link_4" pos="0.7 -0.1 0.97">
          <geom size=".2 .3 .02"  type="box" rgba=".5 .55 .5 1"/>
        </body>
        <body name="box_link_5" pos="0.7 0.38 1.03" euler='0.3 0 0'>
          <geom size=".2 .2 .02"  type="box" rgba=".5 .55 .5 1"/>
        </body>
        <body name="box_link_6" pos="0.55 -0.4 0.97" euler='0 0 -0.3'>
          <geom size=".05 .2 .02"  type="box" rgba=".5 .55 .5 1"/>
        </body>
        <body name="box_link_7" pos="0.85 -0.4 0.97" euler='0 0 0.3'>
          <geom size=".05 .2 .02"  type="box" rgba=".5 .55 .5 1"/>
        </body>



<!--        <body name="bone" pos="0.73 0.02 1" euler='0 0 -1.57'>
            <geom class="panda_viz" mesh="bone_part_viz" rgba="0.6 0.749 1 1"/>
            <geom class="panda_col" mesh="bone_part_col" mass="10"/>
        </body>-->
       <body name="bone" pos="0.63 0.1 1.02" euler='0 0 0'>
            <geom class="panda_viz" mesh="bone_part_viz" rgba="0.6 0.749 1 1"/>
            <geom class="panda_col" mesh="bone_part_col" mass="10"/>
        </body>

        <body name="platform_1" pos="-0.05 0 0" childclass="panda" >
            <geom rgba="0.6 0.749 1 1" class="panda_viz" mesh="platform_viz"/>
            <geom class="panda_col" mesh="platform_col" mass="10"/>
<!--            <geom pos="0.87 -0.3 0.2" euler='0 0 -1.57079632679' class="panda_viz" mesh="bed_viz" rgba=".9 .9 .8 1"/>
            <geom pos="0.87 -0.3 0.2" euler='0 0 -1.57079632679' class="panda_col" mesh="bed_col" mass="2.91242"/>-->
            <body name="panda0_link0" pos="0 0 0.77">
                 <geom class="panda_viz" mesh="link0_viz"/>
                 <geom class="panda_col" mesh="link0_col" mass="2.91242"/>
                 <body name="panda0_link1" pos="0 0 0.333">
                     <joint name="panda0_joint1" range="-2.8973 2.8973" class="panda_arm"/>
                     <geom class="panda_viz" mesh="link1_viz"/>
                     <geom class="panda_col" mesh="link1_col" mass="2.7063"/>
                     <body name="panda0_link2" pos="0 0 0" euler='-1.57079632679 0 0'>
                         <joint name="panda0_joint2" range="-2.7628 2.7628" class="panda_arm"/>
                         <geom class="panda_viz" mesh="link2_viz"/>
                         <geom class="panda_col" mesh="link2_col" mass="2.73046"/>
                         <body name="panda0_link3" pos="0 -0.316 0" euler='1.57079632679 0 0'>
                             <joint name="panda0_joint3" range="-2.8973 2.8973" class="panda_arm"/>
                             <geom class="panda_viz" mesh="link3_viz"/>
                             <geom class="panda_col" mesh="link3_col" mass="2.04104"/>
                             <body name="panda0_link4" pos="0.0825 0 0" euler='1.5708 0 0'><!-- -->
                                 <joint name="panda0_joint4" range="-3.0718 3.0698" class="panda_arm"/>
                                 <geom class="panda_viz" mesh="link4_viz"/>
                                 <geom class="panda_col" mesh="link4_col" mass="2.08129"/>
                                 <body name="panda0_link5" pos="-0.0825 0.384 0" euler='-1.57079632679 0 0'>
                                     <joint name="panda0_joint5" range="-2.8973 2.8973" class="panda_forearm"/>
                                     <geom class="panda_viz" mesh="link5_viz"/>
                                     <geom class="panda_col" mesh="link5_col" mass="3.00049"/>
                                     <body name="panda0_link6" pos="0 0 0" euler='1.57079632679 0 0'>
                                         <joint name="panda0_joint6" range="-3.0175 3.7525" class="panda_forearm"/>
                                         <geom class="panda_viz" mesh="link6_viz"/>
                                         <geom class="panda_col" mesh="link6_col" mass="1.3235"/>
                                         <body name="panda0_link7" pos="0.088 0 0" euler='1.57079632679 0 0'>
                                             <joint name="panda0_joint7" range="-2.8973 2.8973" class="panda_forearm"/>
                                             <geom class="panda_viz" mesh="link7_viz"/>
                                             <geom class="panda_col" mesh="link7_col" mass="0.2"/>
                                             <geom pos="0 0 0.107" euler='0 0 0' class="panda_viz" mesh="grind_viz" />
                                             <geom pos="0 0 0.107" euler='0 0 0' class="panda_col" mesh="grind_col" mass="0.1" />
                                             <site name='end_effector' pos='0 0 .49' size='0.005' />
                                             <site name="touch_sensor_site" pos="0 0 .49" size=".006 .004 .004" rgba=".9 .1 .5 1"/>
                                         </body>
                                     </body>
                                 </body>
                             </body>
                         </body>
                     </body>
                 </body>
             </body>
         </body>
        <body name="platform_2" pos="0.7 -0.72 0"  childclass="panda">
            <geom rgba="0.6 0.749 1 1" class="panda_viz" mesh="platform_viz"/>
            <geom class="panda_col" mesh="platform_col" mass="10"/>
            <body name="panda1_link0" pos="-0.05 0.05 0.77" quat="0.707107 0 0 0.707107" >
                <geom class="panda_viz" mesh="link0_viz"/>
                <geom class="panda_col" mesh="link0_col" mass="2.91242"/>
                <body name="panda1_link1" pos="0 0 0.333">
                    <joint name="panda1_joint1" range="-2.8973 2.8973" class="panda_arm"/>
                    <geom class="panda_viz" mesh="link1_viz"/>
                    <geom class="panda_col" mesh="link1_col" mass="2.7063"/>
                    <body name="panda1_link2" pos="0 0 0" euler='-1.57079632679 0 0'>
                        <joint name="panda1_joint2" range="-1.7628 1.7628" class="panda_arm"/>
                        <geom class="panda_viz" mesh="link2_viz"/>
                        <geom class="panda_col" mesh="link2_col" mass="2.73046"/>
                        <body name="panda1_link3" pos="0 -0.316 0" euler='1.57079632679 0 0'>
                            <joint name="panda1_joint3" range="-2.8973 2.8973" class="panda_arm"/>
                            <geom class="panda_viz" mesh="link3_viz"/>
                            <geom class="panda_col" mesh="link3_col" mass="2.04104"/>
                            <body name="panda1_link4" pos="0.0825 0 0" euler='1.57079632679 0 0'>
                                <joint name="panda1_joint4" range="-3.0718 -0.0698" class="panda_arm"/>
                                <geom class="panda_viz" mesh="link4_viz"/>
                                <geom class="panda_col" mesh="link4_col" mass="2.08129"/>
                               <body name="panda1_link5" pos="-0.0825 0.384 0" euler='-1.57079632679 0 0'>
                                    <joint name="panda1_joint5" range="-2.8973 2.8973" class="panda_forearm"/>
                                    <geom class="panda_viz" mesh="link5_viz"/>
                                    <geom class="panda_col" mesh="link5_col" mass="3.00049"/>
                                    <body name="panda1_link6" pos="0 0 0" euler='1.57079632679 0 0'>
                                        <joint name="panda1_joint6" range="-0.0175 3.7525" class="panda_forearm"/>
                                        <geom class="panda_viz" mesh="link6_viz"/>
                                        <geom class="panda_col" mesh="link6_col" mass="1.3235"/>
                                        <body name="panda1_link7" pos="0.088 0 0" euler='1.57079632679 0 0'>
                                            <joint name="panda1_joint7" range="-2.8973 2.8973" class="panda_forearm"/>
                                            <geom class="panda_viz" mesh="link7_viz"/>
                                            <geom class="panda_col" mesh="link7_col" mass="0.2"/>
                                            <geom pos="0 0 0.131" euler='0 0 0' class="panda_viz" mesh="endscop_viz" />
                                            <geom pos="0 0 0.131" euler='0 0 0' class="panda_col" mesh="endscop_col" mass="0.1" />
                                            <camera name="camera" mode="fixed"  pos="0 0 0" euler='-3.2 0 -0.6235987755982988' fovy = "20"/>
                                        </body>
                                    </body>
                                </body>
                            </body>
                        </body>
                    </body>
                </body>
            </body>
        </body>
        <body name="platform_3" pos="1.45 0 0" euler='0 0 3.14' childclass="panda" >
            <geom rgba="0.6 0.749 1 1" class="panda_viz" mesh="platform_viz"/>
            <geom class="panda_col" mesh="platform_col" mass="10"/>
<!--            <geom pos="0.87 -0.3 0.2" euler='0 0 -1.57079632679' class="panda_viz" mesh="bed_viz" rgba=".9 .9 .8 1"/>
            <geom pos="0.87 -0.3 0.2" euler='0 0 -1.57079632679' class="panda_col" mesh="bed_col" mass="2.91242"/>-->
            <body name="panda2_link0" pos="0 0 0.77">
                 <geom class="panda_viz" mesh="link0_viz"/>
                 <geom class="panda_col" mesh="link0_col" mass="2.91242"/>
                 <body name="panda2_link1" pos="0 0 0.333">
                     <joint name="panda2_joint1" range="-2.8973 2.8973" class="panda_arm"/>
                     <geom class="panda_viz" mesh="link1_viz"/>
                     <geom class="panda_col" mesh="link1_col" mass="2.7063"/>
                     <body name="panda2_link2" pos="0 0 0" euler='-1.57079632679 0 0'>
                         <joint name="panda2_joint2" range="-2.7628 2.7628" class="panda_arm"/>
                         <geom class="panda_viz" mesh="link2_viz"/>
                         <geom class="panda_col" mesh="link2_col" mass="2.73046"/>
                         <body name="panda2_link3" pos="0 -0.316 0" euler='1.57079632679 0 0'>
                             <joint name="panda2_joint3" range="-2.8973 2.8973" class="panda_arm"/>
                             <geom class="panda_viz" mesh="link3_viz"/>
                             <geom class="panda_col" mesh="link3_col" mass="2.04104"/>
                             <body name="panda2_link4" pos="0.0825 0 0" euler='1.5708 0 0'><!-- -->
                                 <joint name="panda2_joint4" range="-3.0718 3.0698" class="panda_arm"/>
                                 <geom class="panda_viz" mesh="link4_viz"/>
                                 <geom class="panda_col" mesh="link4_col" mass="2.08129"/>
                                 <body name="panda2_link5" pos="-0.0825 0.384 0" euler='-1.57079632679 0 0'>
                                     <joint name="panda2_joint5" range="-2.8973 2.8973" class="panda_forearm"/>
                                     <geom class="panda_viz" mesh="link5_viz"/>
                                     <geom class="panda_col" mesh="link5_col" mass="3.00049"/>
                                     <body name="panda2_link6" pos="0 0 0" euler='1.57079632679 0 0'>
                                         <joint name="panda2_joint6" range="-3.0175 3.7525" class="panda_forearm"/>
                                         <geom class="panda_viz" mesh="link6_viz"/>
                                         <geom class="panda_col" mesh="link6_col" mass="1.3235"/>
                                         <body name="panda2_link7" pos="0.088 0 0" euler='1.57079632679 0 0'>
                                             <joint name="panda2_joint7" range="-2.8973 2.8973" class="panda_forearm"/>
                                             <geom class="panda_viz" mesh="link7_viz"/>
                                             <geom class="panda_col" mesh="link7_col" mass="0.2"/>
                                             <geom pos="0 0 0.107" euler='0 0 -0.8' class="panda_viz" mesh="tool3_viz" />
                                             <geom pos="0 0 0.107" euler='0 0 -0.8' class="panda_col" mesh="tool3_col" mass="0.1" />
                                         </body>
                                     </body>
                                 </body>
                             </body>
                         </body>
                     </body>
                 </body>
             </body>
         </body>
    </worldbody>

    <actuator>
        <position name="panda0_joint1" joint="panda0_joint1" class="panda" kp="870" forcerange="-87 87" ctrlrange="-2.9671 2.9671"/> <!-- velocity="2.1750" -->
        <position name="panda0_joint2" joint="panda0_joint2" class="panda" kp="870" forcerange="-87 87" ctrlrange="-2.8326 2.8326"/> <!-- velocity="2.1750" -->
        <position name="panda0_joint3" joint="panda0_joint3" class="panda" kp="870" forcerange="-87 87" ctrlrange="-2.9671 2.9671"/> <!-- velocity="2.1750" -->
        <position name="panda0_joint4" joint="panda0_joint4" class="panda" kp="870" forcerange="-87 87" ctrlrange="-3.1416 2.9"/> <!-- velocity="2.1750" -->
        <position name="panda0_joint5" joint="panda0_joint5" class="panda" kp="870" forcerange="-12 12" ctrlrange="-2.9671 2.9671"/> <!-- velocity="2.6100" -->
        <position name="panda0_joint6" joint="panda0_joint6" class="panda" kp="870" forcerange="-12 12" ctrlrange="-3.7525 2.1817"/> <!-- velocity="2.6100" -->
        <position name="panda0_joint7" joint="panda0_joint7" class="panda" kp="870" forcerange="-12 12" ctrlrange="-2.9671 2.9671"/> <!-- velocity="2.6100" -->

        <position name="panda1_joint1" joint="panda1_joint1" class="panda" kp="870" forcerange="-87 87" ctrlrange="-2.9671 2.9671"/> <!-- velocity="2.1750" -->
        <position name="panda1_joint2" joint="panda1_joint2" class="panda" kp="870" forcerange="-87 87" ctrlrange="-2.8326 2.8326"/> <!-- velocity="2.1750" -->
        <position name="panda1_joint3" joint="panda1_joint3" class="panda" kp="870" forcerange="-87 87" ctrlrange="-2.9671 2.9671"/> <!-- velocity="2.1750" -->
        <position name="panda1_joint4" joint="panda1_joint4" class="panda" kp="870" forcerange="-87 87" ctrlrange="-3.1416 2.6"/> <!-- velocity="2.1750" -->
        <position name="panda1_joint5" joint="panda1_joint5" class="panda" kp="870" forcerange="-12 12" ctrlrange="-2.9671 2.9671"/> <!-- velocity="2.6100" -->
        <position name="panda1_joint6" joint="panda1_joint6" class="panda" kp="870" forcerange="-12 12" ctrlrange="-3.7525 2.6817"/> <!-- velocity="2.6100" -->
        <position name="panda1_joint7" joint="panda1_joint7" class="panda" kp="870" forcerange="-12 12" ctrlrange="-2.9671 2.9671"/> <!-- velocity="2.6100" -->

        <position name="panda2_joint1" joint="panda2_joint1" class="panda" kp="870" forcerange="-87 87" ctrlrange="-2.9671 2.9671"/> <!-- velocity="2.1750" -->
        <position name="panda2_joint2" joint="panda2_joint2" class="panda" kp="870" forcerange="-87 87" ctrlrange="-2.8326 2.8326"/> <!-- velocity="2.1750" -->
        <position name="panda2_joint3" joint="panda2_joint3" class="panda" kp="870" forcerange="-87 87" ctrlrange="-2.9671 2.9671"/> <!-- velocity="2.1750" -->
        <position name="panda2_joint4" joint="panda2_joint4" class="panda" kp="870" forcerange="-87 87" ctrlrange="-3.1416 2.6"/> <!-- velocity="2.1750" -->
        <position name="panda2_joint5" joint="panda2_joint5" class="panda" kp="870" forcerange="-12 12" ctrlrange="-2.9671 2.9671"/> <!-- velocity="2.6100" -->
        <position name="panda2_joint6" joint="panda2_joint6" class="panda" kp="870" forcerange="-12 12" ctrlrange="-3.7525 2.6817"/> <!-- velocity="2.6100" -->
        <position name="panda2_joint7" joint="panda2_joint7" class="panda" kp="870" forcerange="-12 12" ctrlrange="-2.9671 2.9671"/> <!-- velocity="2.6100" -->
    </actuator>

    <sensor>
        <touch name="touch_sensor" 		site="touch_sensor_site"/>

        <jointpos name="panda0_joint1"      joint="panda0_joint1"/>
        <jointpos name="panda0_joint2"      joint="panda0_joint2"/>
        <jointpos name="panda0_joint3"      joint="panda0_joint3"/>
        <jointpos name="panda0_joint4"      joint="panda0_joint4"/>
        <jointpos name="panda0_joint5"      joint="panda0_joint5"/>
        <jointpos name="panda0_joint6"      joint="panda0_joint6"/>
        <jointpos name="panda0_joint7"      joint="panda0_joint7"/>


    </sensor>




</mujoco>






































































