<mujoco model="franka">

   <compiler angle="radian" inertiafromgeom="true" meshdir="meshes/" />
   <option timestep="0.002"/>
   <size nuser_actuator="5"/>

   <asset>
        <mesh name="link0_col" file="collision/link0.stl"/>
        <mesh name="link1_col" file="collision/link1.stl"/>
        <mesh name="link2_col" file="collision/link2.stl"/>
        <mesh name="link3_col" file="collision/link3.stl"/>
        <mesh name="link4_col" file="collision/link4.stl"/>
        <mesh name="link5_col" file="collision/link5.stl"/>
        <mesh name="link6_col" file="collision/link6.stl"/>
        <mesh name="link7_col" file="collision/link7.stl"/>
        <mesh name="sensor_col" file="collision/sensor.stl"/>
        <mesh name="grind_col" file="collision/grind.stl"/>
        <mesh name="endscop_col" file="collision/endscop.stl"/>


        <mesh name="link0_viz" file="visual/link0.stl"/>
        <mesh name="link1_viz" file="visual/link1.stl"/>
        <mesh name="link2_viz" file="visual/link2.stl"/>
        <mesh name="link3_viz" file="visual/link3.stl"/>
        <mesh name="link4_viz" file="visual/link4.stl"/>
        <mesh name="link5_viz" file="visual/link5.stl"/>
        <mesh name="link6_viz" file="visual/link6.stl"/>
        <mesh name="link7_viz" file="visual/link7.stl"/>
        <mesh name="sensor_viz" file="visual/sensor.stl"/>
        <mesh name="grind_viz" file="visual/grind.stl"/>
        <mesh name="endscop_viz" file="visual/endscop.stl"/>

        <texture name="floor_tex"   type="2d"       builtin="checker"  rgb1=".2 .3 .4" rgb2=".1 .2 .3" width="100" height="100" />
        <texture name="sky_tex"     type="skybox"   builtin="gradient" width="100"     height="100"    rgb1="1 1 1" rgb2="0.3 0.3 0.8" />

        <material name='floor_mat'      texture="floor_tex"  shininess="0.8" texrepeat="10 10" specular="0.7"  reflectance="0.5" />
    </asset>

    <default>
        <default class="panda">
            <joint pos="0 0 0" axis="0 0 1" limited="true"/>
            <position forcelimited="true" ctrllimited="true" user="1002 40 2001 -0.005 0.005"/>
            <default class="panda_viz">
                <geom contype="0" conaffinity="0" group="0" type="mesh" rgba=".95 .99 .92 1" mass="0"/>
            </default>

            <default class="panda_col">
                <geom contype="1" conaffinity="1" group="3" type="mesh" rgba=".5 .6 .7 1"/>
            </default>

            <default class="panda_arm">
                <joint damping="100"/>
            </default>
             <default class="panda_forearm">
                <joint damping="10"/>
            </default>
             <default class="panda_finger">
                <joint damping="100" armature='5'/>
                <geom friction="1 0.5 0.0001" solref="0.01 1" solimp="0.8 0.9 0.001" margin="0.001" user="0" rgba="0.5 0.6 0.7 .4" contype="1" conaffinity="0" condim="6" group="3" />
                <position user="1002 40 2001 -0.0001 0.0001"/>
            </default>
        </default>

        <default class="panda_overlay">
            <joint limited="false" damping="1000" armature="1" frictionloss="10"/>
            <geom contype="0" conaffinity="0" group="2" type="mesh" rgba=".42 0.42 0.42 .5"/>
        </default>
    </default>

    <worldbody>
        <light directional="true" cutoff="4" exponent="20" diffuse="1 1 1" specular="0 0 0" pos="1 1 3" dir="-.5 -0.75 -1.5"/>
<!--        <camera name="camera" mode="fixed" target="panda1_link7" pos="0.5 0 0"/>-->
        <geom name='floor' material="floor_mat" pos='0 0 0' size='2.5 2.5 0.1'  type='plane' />


        <body name="box_link" pos="0.6 0 0.3">
          <geom size=".2 .3 .001"  type="box" rgba=".5 .55 .5 1"/>
        </body>
        <body name="grasp_link_1" pos="0.57 0 0.4">
          <freejoint/>
          <geom  size=".01 .01 .01"  type="box" rgba="0 .96 1 1" mass="0.1"/>
        </body>
        <body name="grasp_link_2" pos="0.57 -0.02 0.4">
          <freejoint/>
          <geom  size=".01 .01 .01"  type="box" rgba=".94 .1 .94 1" mass="0.1"/>
        </body>
        <body name="grasp_link_3" pos="0.57 0.02 0.4">
          <freejoint/>
          <geom  size=".01 .01 .01"  type="box" rgba="0 1 .498 1" mass="0.1"/>
        </body>
        <body name="grasp_link_4" pos="0.57 -0.05 0.4">
          <freejoint/>
          <geom  size=".01 .01 .01"  type="box" rgba="0 .749 1 1" mass="0.1"/>
        </body>

        <body name="panda0_link0" childclass="panda" >
             <geom class="panda_viz" mesh="link0_viz"/>
             <geom class="panda_col" mesh="link0_col" mass="2.91242"/>
             <body name="panda0_link1" pos="0 0 0.333">
                 <joint name="panda0_joint1" range="-2.8973 2.8973" class="panda_arm"/>
                 <geom class="panda_viz" mesh="link1_viz"/>
                 <geom class="panda_col" mesh="link1_col" mass="2.7063"/>
                 <body name="panda0_link2" pos="0 0 0" euler='-1.57079632679 0 0'>
                     <joint name="panda0_joint2" range="-2.7628 2.7628" class="panda_arm"/>
                     <geom class="panda_viz" mesh="link2_viz"/>
                     <geom class="panda_col" mesh="link2_col" mass="2.73046"/>
                     <body name="panda0_link3" pos="0 -0.316 0" euler='1.57079632679 0 0'>
                         <joint name="panda0_joint3" range="-2.8973 2.8973" class="panda_arm"/>
                         <geom class="panda_viz" mesh="link3_viz"/>
                         <geom class="panda_col" mesh="link3_col" mass="2.04104"/>
                         <body name="panda0_link4" pos="0.0825 0 0" euler='1.5708 0 0'><!-- -->
                             <joint name="panda0_joint4" range="-3.0718 3.0698" class="panda_arm"/>
                             <geom class="panda_viz" mesh="link4_viz"/>
                             <geom class="panda_col" mesh="link4_col" mass="2.08129"/>
                             <body name="panda0_link5" pos="-0.0825 0.384 0" euler='-1.57079632679 0 0'>
                                 <joint name="panda0_joint5" range="-2.8973 2.8973" class="panda_forearm"/>
                                 <geom class="panda_viz" mesh="link5_viz"/>
                                 <geom class="panda_col" mesh="link5_col" mass="3.00049"/>
                                 <body name="panda0_link6" pos="0 0 0" euler='1.57079632679 0 0'>
                                     <joint name="panda0_joint6" range="-3.0175 3.7525" class="panda_forearm"/>
                                     <geom class="panda_viz" mesh="link6_viz"/>
                                     <geom class="panda_col" mesh="link6_col" mass="1.3235"/>
                                     <body name="panda0_link7" pos="0.088 0 0" euler='1.57079632679 0 0'>
                                         <joint name="panda0_joint7" range="-2.8973 2.8973" class="panda_forearm"/>
                                         <geom class="panda_viz" mesh="link7_viz"/>
                                         <geom class="panda_col" mesh="link7_col" mass="0.2"/>
                                         <geom pos="0 0 0.107" euler='0 0 0' class="panda_viz" mesh="grind_viz" />
                                         <geom pos="0 0 0.107" euler='0 0 0' class="panda_col" mesh="grind_col" mass="0.1" />
                                         <site name='end_effector' pos='0 0 .49' size='0.005' />
                                         <site name="touch_sensor_site" pos="0 0 .49" size=".006 .004 .004" rgba=".9 .1 .5 1"/>
                                     </body>
                                 </body>
                             </body>
                         </body>
                     </body>
                 </body>
             </body>
         </body>
        <body name="panda1_link0" pos="0.55 -0.6 0" quat="0.707107 0 0 0.707107" childclass="panda" >
            <geom class="panda_viz" mesh="link0_viz"/>
            <geom class="panda_col" mesh="link0_col" mass="2.91242"/>
            <body name="panda1_link1" pos="0 0 0.333">
                <joint name="panda1_joint1" range="-2.8973 2.8973" class="panda_arm"/>
                <geom class="panda_viz" mesh="link1_viz"/>
                <geom class="panda_col" mesh="link1_col" mass="2.7063"/>
                <body name="panda1_link2" pos="0 0 0" euler='-1.57079632679 0 0'>
                    <joint name="panda1_joint2" range="-1.7628 1.7628" class="panda_arm"/>
                    <geom class="panda_viz" mesh="link2_viz"/>
                    <geom class="panda_col" mesh="link2_col" mass="2.73046"/>
                    <body name="panda1_link3" pos="0 -0.316 0" euler='1.57079632679 0 0'>
                        <joint name="panda1_joint3" range="-2.8973 2.8973" class="panda_arm"/>
                        <geom class="panda_viz" mesh="link3_viz"/>
                        <geom class="panda_col" mesh="link3_col" mass="2.04104"/>
                        <body name="panda1_link4" pos="0.0825 0 0" euler='1.57079632679 0 0'>
                            <joint name="panda1_joint4" range="-3.0718 -0.0698" class="panda_arm"/>
                            <geom class="panda_viz" mesh="link4_viz"/>
                            <geom class="panda_col" mesh="link4_col" mass="2.08129"/>
                           <body name="panda1_link5" pos="-0.0825 0.384 0" euler='-1.57079632679 0 0'>
                                <joint name="panda1_joint5" range="-2.8973 2.8973" class="panda_forearm"/>
                                <geom class="panda_viz" mesh="link5_viz"/>
                                <geom class="panda_col" mesh="link5_col" mass="3.00049"/>
                                <body name="panda1_link6" pos="0 0 0" euler='1.57079632679 0 0'>
                                    <joint name="panda1_joint6" range="-0.0175 3.7525" class="panda_forearm"/>
                                    <geom class="panda_viz" mesh="link6_viz"/>
                                    <geom class="panda_col" mesh="link6_col" mass="1.3235"/>
                                    <body name="panda1_link7" pos="0.088 0 0" euler='1.57079632679 0 0'>
                                        <joint name="panda1_joint7" range="-2.8973 2.8973" class="panda_forearm"/>
                                        <geom class="panda_viz" mesh="link7_viz"/>
                                        <geom class="panda_col" mesh="link7_col" mass="0.2"/>
                                        <geom pos="0 0 0.131" euler='0 0 0' class="panda_viz" mesh="endscop_viz" />
                                        <geom pos="0 0 0.131" euler='0 0 0' class="panda_col" mesh="endscop_col" mass="0.1" />
                                        <camera name="camera" mode="fixed"  pos="0 0 0" euler='-3.2 0 -0.6235987755982988'/>
                                    </body>
                                </body>
                            </body>
                        </body>
                    </body>
                </body>
            </body>
        </body>
    </worldbody>

    <actuator>
        <position name="panda0_joint1" joint="panda0_joint1" class="panda" kp="870" forcerange="-87 87" ctrlrange="-2.9671 2.9671"/> <!-- velocity="2.1750" -->
        <position name="panda0_joint2" joint="panda0_joint2" class="panda" kp="870" forcerange="-87 87" ctrlrange="-2.8326 2.8326"/> <!-- velocity="2.1750" -->
        <position name="panda0_joint3" joint="panda0_joint3" class="panda" kp="870" forcerange="-87 87" ctrlrange="-2.9671 2.9671"/> <!-- velocity="2.1750" -->
        <position name="panda0_joint4" joint="panda0_joint4" class="panda" kp="870" forcerange="-87 87" ctrlrange="-3.1416 2.9"/> <!-- velocity="2.1750" -->
        <position name="panda0_joint5" joint="panda0_joint5" class="panda" kp="870" forcerange="-12 12" ctrlrange="-2.9671 2.9671"/> <!-- velocity="2.6100" -->
        <position name="panda0_joint6" joint="panda0_joint6" class="panda" kp="870" forcerange="-12 12" ctrlrange="-3.7525 2.1817"/> <!-- velocity="2.6100" -->
        <position name="panda0_joint7" joint="panda0_joint7" class="panda" kp="870" forcerange="-12 12" ctrlrange="-2.9671 2.9671"/> <!-- velocity="2.6100" -->

        <position name="panda1_joint1" joint="panda1_joint1" class="panda" kp="870" forcerange="-87 87" ctrlrange="-2.9671 2.9671"/> <!-- velocity="2.1750" -->
        <position name="panda1_joint2" joint="panda1_joint2" class="panda" kp="870" forcerange="-87 87" ctrlrange="-1.8326 1.8326"/> <!-- velocity="2.1750" -->
        <position name="panda1_joint3" joint="panda1_joint3" class="panda" kp="870" forcerange="-87 87" ctrlrange="-2.9671 2.9671"/> <!-- velocity="2.1750" -->
        <position name="panda1_joint4" joint="panda1_joint4" class="panda" kp="870" forcerange="-87 87" ctrlrange="-3.1416 2.0"/> <!-- velocity="2.1750" -->
        <position name="panda1_joint5" joint="panda1_joint5" class="panda" kp="120" forcerange="-12 12" ctrlrange="-2.9671 2.9671"/> <!-- velocity="2.6100" -->
        <position name="panda1_joint6" joint="panda1_joint6" class="panda" kp="120" forcerange="-12 12" ctrlrange="-3.7525 2.1817"/> <!-- velocity="2.6100" -->
        <position name="panda1_joint7" joint="panda1_joint7" class="panda" kp="120" forcerange="-12 12" ctrlrange="-2.9671 2.9671"/> <!-- velocity="2.6100" -->
    </actuator>

    <sensor>
        <touch name="touch_sensor" 		site="touch_sensor_site"/>

        <jointpos name="panda0_joint1"      joint="panda0_joint1"/>
        <jointpos name="panda0_joint2"      joint="panda0_joint2"/>
        <jointpos name="panda0_joint3"      joint="panda0_joint3"/>
        <jointpos name="panda0_joint4"      joint="panda0_joint4"/>
        <jointpos name="panda0_joint5"      joint="panda0_joint5"/>
        <jointpos name="panda0_joint6"      joint="panda0_joint6"/>
        <jointpos name="panda0_joint7"      joint="panda0_joint7"/>


    </sensor>




</mujoco>






































































